Workbook

Sheet data
A2: EXP 1 | F2: EXP 1
A4: 3 turns large
A6: I coil (A) | C6: I loop (A) | D6: dynamometer reading
A8: 2.6 | C8: 1.5 | D8: 1
A9: 2.2 | C9: 1.5 | D9: 0.9
A10: 1.8 | C10: 1.5 | D10: 0.7
A11: 1.4 | C11: 1.5 | D11: 0.56
A12: 1 | C12: 1.5 | D12: 0.35
A13: 0.6 | C13: 1.5 | D13: 0.2
A14: 0.2 | C14: 1.5 | D14: 0.1
A15: -0.2 | C15: 1.5 | D15: -0.1
A16: -0.6 | C16: 1.5 | D16: -0.24
A17: -1 | C17: 1.5 | D17: -0.4
A18: -1.4 | C18: 1.5 | D18: -0.5
A19: -1.8 | C19: 1.5 | D19: -0.64
... A21: -2.6 | C21: 1.5 | D21: -0.9
A22: EXP 1 | E22: dynamometer readings
A23: Rd1 | B23: Rd2 | C23: Rd3 | D23: IL (A) | E23: Rd1 | F23: Rd2 | G23: Rd3 | I23: Ih average readings | J23: dynamometer readings average | L23: corrected rd1 to rd3 data
A24: Ih (A) | B24: ih(A) | C24: ih(A)
K25: dynamometer proper | N25: {=AVERAGE(ABS(J26:J52))} -> 0.57444444
A26: 2.6 | B26: 2.6 | C26: 2.6 | D26: 1.8 | E26: 1.1 | F26: 1.1 | G26: 1.1 | I26: =AVERAGE(A26:C26) -> 2.6 | J26: =AVERAGE(E26:G26) -> 1.1 | K26: =J26*0.11/1000 -> 0.000121 | N26: {=AVERAGE(ABS(I26:I52))} -> 1.3480247
A27: 2.4 | B27: 2.4 | C27: 2.4 | D27: 1.8 | E27: 1 | F27: 1 | G27: 1 | I27: =AVERAGE(A27:C27) -> 2.4 | J27: =AVERAGE(E27:G27) -> 1 | K27: =J27*0.11/1000 -> 0.00011
A28: 2.2 | B28: 2.2 | C28: 2.2 | D28: 1.8 | E28: 0.9 | F28: 0.9 | G28: 0.9 | I28: =AVERAGE(A28:C28) -> 2.2 | J28: =AVERAGE(E28:G28) -> 0.9 | K28: =J28*0.11/1000 -> 9.9e-05
A29: 2 | B29: 2 | C29: 2 | D29: 1.8 | E29: 0.8 | F29: 0.8 | G29: 0.8 | I29: =AVERAGE(A29:C29) -> 2 | J29: =AVERAGE(E29:G29) -> 0.8 | K29: =J29*0.11/1000 -> 8.8e-05
A30: 1.8 | B30: 1.8 | C30: 1.8 | D30: 1.8 | E30: 0.7 | F30: 0.7 | G30: 0.73 | I30: =AVERAGE(A30:C30) -> 1.8 | J30: =AVERAGE(E30:G30) -> 0.71 | K30: =J30*0.11/1000 -> 7.81e-05
A31: 1.59 | B31: 1.59 | C31: 1.59 | D31: 1.8 | E31: 0.66 | F31: 0.66 | G31: 0.66 | I31: =AVERAGE(A31:C31) -> 1.59 | J31: =AVERAGE(E31:G31) -> 0.66 | K31: =J31*0.11/1000 -> 7.26e-05
A32: 1.39 | B32: 1.4 | C32: 1.41 | D32: 1.8 | E32: 0.6 | F32: 0.5 | G32: 0.54 | I32: =AVERAGE(A32:C32) -> 1.4 | J32: =AVERAGE(E32:G32) -> 0.54666667 | K32: =J32*0.11/1000 -> 6.0133333e-05
A33: 1.2 | B33: 1.2 | C33: 1.2 | D33: 1.8 | E33: 0.54 | F33: 0.54 | G33: 0.54 | I33: =AVERAGE(A33:C33) -> 1.2 | J33: =AVERAGE(E33:G33) -> 0.54 | K33: =J33*0.11/1000 -> 5.94e-05
A34: 1 | B34: 1 | C34: 0.99 | D34: 1.8 | E34: 0.4 | F34: 0.4 | G34: 0.4 | I34: =AVERAGE(A34:C34) -> 0.99666667 | J34: =AVERAGE(E34:G34) -> 0.4 | K34: =J34*0.11/1000 -> 4.4e-05
A35: 0.8 | B35: 0.8 | C35: 0.8 | D35: 1.79 | E35: 0.3 | F35: 0.3 | G35: 0.3 | I35: =AVERAGE(A35:C35) -> 0.8 | J35: =AVERAGE(E35:G35) -> 0.3 | K35: =J35*0.11/1000 -> 3.3e-05
A36: 0.6 | B36: 0.61 | C36: 0.6 | D36: 1.79 | E36: 0.3 | F36: 0.3 | G36: 0.2 | I36: =AVERAGE(A36:C36) -> 0.60333333 | J36: =AVERAGE(E36:G36) -> 0.26666667 | K36: =J36*0.11/1000 -> 2.9333333e-05
A37: 0.4 | B37: 0.4 | C37: 0.4 | D37: 1.79 | E37: 0.25 | F37: 0.25 | G37: 0.25 | I37: =AVERAGE(A37:C37) -> 0.4 | J37: =AVERAGE(E37:G37) -> 0.25 | K37: =J37*0.11/1000 -> 2.75e-05
A38: 0.2 | B38: 0.2 | C38: 0.2 | D38: 1.79 | E38: 0.1 | F38: 0.1 | G38: 0.1 | I38: =AVERAGE(A38:C38) -> 0.2 | J38: =AVERAGE(E38:G38) -> 0.1 | K38: =J38*0.11/1000 -> 1.1e-05 | Q38: slope= (in SI) | R38: {=LINEST(K26:K52,I26:I52)} -> 4.6457478e-05 | S38: -1.4515695e-06
A39: 0 | B39: 0 | C39: 0 | D39: 1.79 | E39: 0 | F39: 0 | G39: 0 | I39: =AVERAGE(A39:C39) -> 0 | J39: =AVERAGE(E39:G39) -> 0 | K39: =J39*0.11/1000 -> 0
A40: -0.2 | B40: -0.2 | C40: -0.2 | D40: 1.79 | E40: -0.1 | F40: -0.1 | G40: -0.1 | I40: =AVERAGE(A40:C40) -> -0.2 | J40: =AVERAGE(E40:G40) -> -0.1 | K40: =J40*0.11/1000 -> -1.1e-05
A41: -0.4 | B41: -0.4 | C41: -0.4 | D41: 1.8 | E41: -0.2 | F41: -0.2 | G41: -0.2 | I41: =AVERAGE(A41:C41) -> -0.4 | J41: =AVERAGE(E41:G41) -> -0.2 | K41: =J41*0.11/1000 -> -2.2e-05
A42: -0.6 | B42: -0.6 | C42: -0.6 | D42: 1.8 | E42: -0.25 | F42: -0.3 | G42: -0.3 | I42: =AVERAGE(A42:C42) -> -0.6 | J42: =AVERAGE(E42:G42) -> -0.28333333 | K42: =J42*0.11/1000 -> -3.1166667e-05
A43: -0.8 | B43: -0.8 | C43: -0.8 | D43: 1.8 | E43: -0.35 | F43: -0.35 | G43: -0.35 | I43: =AVERAGE(A43:C43) -> -0.8 | J43: =AVERAGE(E43:G43) -> -0.35 | K43: =J43*0.11/1000 -> -3.85e-05
A44: -1 | B44: -1 | C44: -1 | D44: 1.8 | E44: -0.47 | F44: -0.5 | G44: -0.44 | I44: =AVERAGE(A44:C44) -> -1 | J44: =AVERAGE(E44:G44) -> -0.47 | K44: =J44*0.11/1000 -> -5.17e-05
A45: -1.2 | B45: -1.2 | C45: -1.2 | D45: 1.8 | E45: -0.5 | F45: -0.5 | G45: -0.5 | I45: =AVERAGE(A45:C45) -> -1.2 | J45: =AVERAGE(E45:G45) -> -0.5 | K45: =J45*0.11/1000 -> -5.5e-05
...

Sheet results and error analysis
A1: helmholtz coil radius = | C1: inner = | D1: 18cm | E1: outer= | F1: 21.5
A2: therefore midpoint to midpoint R= | D2: 20cm
D4: mu naught= | E4: 1.2566371e-06 | F4: 3.1415927
A5: helmholtz coil radius = | C5: 0.2 m | D5: N= | E5: 154 turns
A6: theoretical value = | C6: =(8*E4*154)/(5*SQRT(5)*0.1975) -> 0.00070112986
C7: general formula: | D7: T= | E7: c*n*Ih*Il*(pi*d^2)*sin(a)/4
A9: exp1 | B9: Il=1.8 A | C9: n=3 | D9: d=12cm | E9: T vs Ih
A10: slope= | B10: =data!R38 -> 4.6457478e-05 | D10: slope error (relative) = | F10: =SQRT(H10^2 + H11^2) -> 0.087356167 | G10: relative error in T= | H10: =0.05/data!N25 -> 0.087040619
A11: c= | B11: =B10/(3*1.8*PI()*(0.12^2)*1/4) -> 0.00076069314 | G11: relative error in Ih= | H11: =0.01/data!N26 -> 0.0074182617
A12: discrepency= | B12: =C6/B11 -> 0.92169868 | C12: =(1-B12)*100 -> 7.8301315
D13: relative error in c | F13: =SQRT(F10^2 +H13^2) -> 0.087360142 | G13: relative error in d= | H13: =0.1/120 -> 0.00083333333
D14: absolute error in c= | F14: =F13*B11 -> 6.645426e-05 | G14: (cos 90=0 therefore error for angle negligible)
D15: values * 10^4 | E15: =B11*10^4 -> 7.6069314 | F15: =F14*10^4 -> 0.6645426
A18: exp2 | B18: Ih=2.6A | C18: Il=1.5 A | D18: (dependence on n) | E18: d=0.12 cm | F18: T vs n
A19: slope= | B19: =data!F96 -> 3.3e-05 | D19: slope error (relative) = | F19: =H19 -> 0.083333333 | G19: relative error in T= | H19: =0.05/0.6 -> 0.083333333
A20: c= | B20: =B19/(2.6*1.5*PI()*(0.12^2)/4) -> 0.00074816426
A21: discrepency= | B21: =C6/B20 -> 0.93713359 | C21: =(1-B21)*100 -> 6.2866407
D22: relative error in c | F22: =SQRT(F19^2+ 2*H13^2) -> 0.083341666
A23: =1-(C6/0.00075) -> 0.065160182 | D23: absolute error in c= | F23: =B20*F22 -> 6.2353256e-05
D24: values * 10^4 | E24: =B20*10^4 -> 7.4816426 | F24: =F23*10^4 -> 0.62353256
A27: exp3 | B27: (dependence on angle) | D27: Ih=2.6A | E27: Il= 2.5A | F27: n=3 | G27: d=0.12 | H27: T vs sin(a)
A28: slope= | B28: =data!U66 -> 0.00015167966 | D28: slope error (relative) = | F28: =SQRT(H28^2+H29^2) -> 0.057754043 | G28: relative error inT= | H28: =0.05/data!G78 -> 0.053941909
A29: c= | B29: =B28/(3*2.6*2.5*PI()*(0.12^2)/4) -> 0.00068776547 | G29: relative error in angle= | H29: =1/data!G79 -> 0.020634921
A30: discrepency= | B30: =C6/B29 -> 1.0194316 | C30: =(1-B30)*100 -> -1.9431621
D31: relative error in c | F31: =SQRT(F28^2 + 2*H13^2) -> 0.057766066
A32: discrepency = | B32: =1-0.00069/C6 -> 0.015874182 | D32: absolute error in c= | F32: =B29*F31 -> 3.9729505e-05
D33: values * 10^4 | E33: =B29*10^4 -> 6.8776547 | F33: =F32*10^4 -> 0.39729505
A36: exp4 | B36: (dependence on Il) | D36: Ih=2.6A | E36: n=3 | F36: d=0.12 | H36: T vs Il
A37: slope= | B37: =data!AA116 -> 6.4916303e-05 | D37: slope error (relative) = | F37: =SQRT(H37^2 +H38^2) -> 0.033292355 | G37: relative error in T= | H37: =0.05/data!Q128 -> 0.033061066
A38: c= | B38: =B37/(3*2.6*PI()*(0.12^2)/4) -> 0.00073587966 | G38: relative error in Il= | H38: =0.01/data!Q129 -> 0.003917502
A39: discrepency= | B39: =C6/B38 -> 0.95277788 | C39: =(1-B39)*100 -> 4.7222124
D40: relative error in c | F40: =SQRT(F37^2 + 2*H13^2) -> 0.033313207
D41: absolute error in c= | F41: =B38*F40 -> 2.4514512e-05
D42: values * 10^4 | E42: =B38*10^4 -> 7.3587966 | F42: =F41*10^4 -> 0.24514512
A45: exp5 | B45: (dependence on d^2) | D45: n=1 | E45: Ih=2.6 A | F45: Il=4 A | H45: T vs d^2
A46: slope= | B46: =data!X91 -> 0.0058651901 | D46: slope error (relative) = | F46: =SQRT(H46^2 + 2*H47^2) -> 0.10490725 | G46: relative error in T= | H46: =0.05/data!P88 -> 0.1048951
A47: c= | B47: =B46/(1*2.6*4*PI()/4) -> 0.00071805691 | G47: relative error in d= | H47: =0.0001/data!P89 -> 0.0011286682
A48: discrepency= | B48: =C6/B47 -> 0.97642659 | C48: =(1-B48)*100 -> 2.3573412
D49: relative error in c | F49: =F46 -> 0.10490725
A50: discrepency= | B50: =1-0.00072/C6 -> -0.026913897 | D50: absolute error in c= | F50: =B47*F49 -> 7.5329375e-05
...
